<?xml version="1.0" ?>
<!-- =================================================================================== -->
<!-- |    This document was autogenerated by xacro from TwoJointRobot_woCyl.xacro      | -->
<!-- |    EDITING THIS FILE BY HAND IS NOT RECOMMENDED                                 | -->
<!-- =================================================================================== -->
<robot name="FourJointRobot"
  xmlns:xacro="http://www.ros.org/wiki/xacro">
  <material name="blue">
    <color rgba="0 0 0.8 1"/>
  </material>
  <material name="white">
    <color rgba="0 1 0 1"/>
  </material>

  <link name="base_link">
    <visual>
      <geometry>
        <sphere radius="0.1"/>
      </geometry>
    </visual>
    <collision>
      <geometry>
        <sphere radius="0.1"/>
      </geometry>
    </collision>
    <inertial>
      <origin xyz="0 0 0" rpy="0 0 0"/>
      <mass value="0"/>
      <inertia ixx="0.001" ixy="0.0" ixz="0.0" iyy="0.001" iyz="0.0" izz="0.001"/>
    </inertial>
  </link>

  <link name="link_1">
    <visual>
      <geometry>
        <box size="1.0 0.1 0.05"/>
      </geometry>
      <origin rpy="0 0 0" xyz="0.5 0 0"/>
      <material name="white"/>
    </visual>
    <collision>
      <geometry>
        <box size="1.0 0.1 0.05"/>
      </geometry>
      <origin rpy="0 0 0" xyz="0.5 0 0"/>
    </collision>
    <inertial>
      <origin xyz="1 0 0" rpy="0 0 0"/>
      <mass value="1"/>
      <inertia ixx="0.00001" ixy="0.0" ixz="0.0" iyy="0.00001" iyz="0.0" izz="0.00001"/>
    </inertial>
  </link>
  <joint name="joint_1" type="revolute">
    <safety_controller k_position="400.0" k_velocity="40.0" soft_lower_limit="-2.8973" soft_upper_limit="2.8973"/>
    <axis xyz="0 0 1"/>
    <limit effort="10000" lower="-3.14" upper="3.14" velocity="500"/>
    <origin rpy="1.570796 0 0" xyz="0 0 0"/>
    <parent link="base_link"/>
    <child link="link_1"/>
    <controller k_t="2.0" k_s="0.05" k_p="10000.0" k_d="200.0"/>
    <properties inertia="0.95992" stiffness="10957" damping="1"/>
    <home value="2"/>
  </joint>

  <link name="link_2">
    <visual>
      <geometry>
        <box size="1.0 0.1 0.05"/>
      </geometry>
      <origin rpy="0 0 0" xyz="0.5 0 0"/>
      <material name="white"/>
    </visual>
    <collision>
      <geometry>
        <box size="1.0 0.1 0.05"/>
      </geometry>
      <origin rpy="0 0 0" xyz="0.5 0 0"/>
    </collision>
    <inertial>
      <origin xyz="1 0 0" rpy="0 0 0"/>
      <mass value="1"/>
      <inertia ixx="0.00001" ixy="0.0" ixz="0.0" iyy="0.00001" iyz="0.0" izz="0.00001"/>
    </inertial>
  </link>
  <joint name="joint_2" type="revolute">
    <safety_controller k_position="400.0" k_velocity="40.0" soft_lower_limit="-2.8973" soft_upper_limit="2.8973"/>
    <axis xyz="0 0 1"/>
    <limit effort="10000" lower="-3.14" upper="3.14" velocity="500"/>
    <origin rpy="0 0 0" xyz="1.0 0 0"/>
    <parent link="link_1"/>
    <child link="link_2"/>
    <controller k_t="2.0" k_s="0.05" k_p="10000.0" k_d="200.0"/>
    <properties inertia="0.95992" stiffness="10957" damping="1"/>
    <home value="-1.57"/>
  </joint>

  <link name="link_3">
    <visual>
      <geometry>
        <box size="1.0 0.1 0.05"/>
      </geometry>
      <origin rpy="0 0 0" xyz="0.5 0 0"/>
      <material name="white"/>
    </visual>
    <collision>
      <geometry>
        <box size="1.0 0.1 0.05"/>
      </geometry>
      <origin rpy="0 0 0" xyz="0.5 0 0"/>
    </collision>
    <inertial>
      <origin xyz="1 0 0" rpy="0 0 0"/>
      <mass value="1"/>
      <inertia ixx="0.00001" ixy="0.0" ixz="0.0" iyy="0.00001" iyz="0.0" izz="0.00001"/>
    </inertial>
  </link>
  <joint name="joint_3" type="revolute">
    <safety_controller k_position="400.0" k_velocity="40.0" soft_lower_limit="-2.8973" soft_upper_limit="2.8973"/>
    <axis xyz="0 0 1"/>
    <limit effort="10000" lower="-3.14" upper="3.14" velocity="500"/>
    <origin rpy="0 0 0" xyz="1.0 0 0"/>
    <parent link="link_2"/>
    <child link="link_3"/>
    <controller k_t="2.0" k_s="0.05" k_p="10000.0" k_d="200.0"/>
    <properties inertia="0.95992" stiffness="10957" damping="1"/>
    <home value="-0.5"/>
  </joint>

  <link name="link_4">
    <visual>
      <geometry>
        <box size="1.0 0.1 0.05"/>
      </geometry>
      <origin rpy="0 0 0" xyz="0.5 0 0"/>
      <material name="white"/>
    </visual>
    <collision>
      <geometry>
        <box size="1.0 0.1 0.05"/>
      </geometry>
      <origin rpy="0 0 0" xyz="0.5 0 0"/>
    </collision>
    <inertial>
      <origin xyz="1 0 0" rpy="0 0 0"/>
      <mass value="1"/>
      <inertia ixx="0.00001" ixy="0.0" ixz="0.0" iyy="0.00001" iyz="0.0" izz="0.00001"/>
    </inertial>
  </link>
  <joint name="joint_4" type="revolute">
    <safety_controller k_position="400.0" k_velocity="40.0" soft_lower_limit="-2.8973" soft_upper_limit="2.8973"/>
    <axis xyz="0 0 1"/>
    <limit effort="10000" lower="-3.14" upper="3.14" velocity="500"/>
    <origin rpy="0 0 0" xyz="1.0 0 0"/>
    <parent link="link_3"/>
    <child link="link_4"/>
    <controller k_t="2.0" k_s="0.05" k_p="10000.0" k_d="200.0"/>
    <properties inertia="0.95992" stiffness="10957" damping="1"/>
    <home value="-0.5"/>
  </joint>

</robot>

